Traceback (most recent call last):
  File "/data/isip/exp/tuh_dpath/exp_0280/nedc_mladp/bin/./nedc_mladp_eval", line 21, in <module>
    import nedc_mladp_eval_tools as eval_tools
  File "/data/isip/exp/tuh_dpath/exp_0280/nedc_mladp/lib/nedc_mladp_eval_tools.py", line 7, in <module>
    import polars
ModuleNotFoundError: No module named 'polars'
Traceback (most recent call last):
  File "/data/isip/exp/tuh_dpath/exp_0280/nedc_mladp/bin/./nedc_mladp_eval", line 21, in <module>
    import nedc_mladp_eval_tools as eval_tools
  File "/data/isip/exp/tuh_dpath/exp_0280/nedc_mladp/lib/nedc_mladp_eval_tools.py", line 7, in <module>
    import polars
ModuleNotFoundError: No module named 'polars'
Traceback (most recent call last):
  File "/data/isip/exp/tuh_dpath/exp_0280/nedc_mladp/bin/./nedc_mladp_eval", line 21, in <module>
    import nedc_mladp_eval_tools as eval_tools
  File "/data/isip/exp/tuh_dpath/exp_0280/nedc_mladp/lib/nedc_mladp_eval_tools.py", line 7, in <module>
    import polars
ModuleNotFoundError: No module named 'polars'
Traceback (most recent call last):
  File "/data/isip/exp/tuh_dpath/exp_0280/nedc_mladp/bin/./nedc_mladp_eval", line 21, in <module>
    import nedc_mladp_eval_tools as eval_tools
  File "/data/isip/exp/tuh_dpath/exp_0280/nedc_mladp/lib/nedc_mladp_eval_tools.py", line 7, in <module>
    import polars
ModuleNotFoundError: No module named 'polars'
Traceback (most recent call last):
  File "/data/isip/exp/tuh_dpath/exp_0280/nedc_mladp/bin/./nedc_mladp_eval", line 21, in <module>
    import nedc_mladp_eval_tools as eval_tools
  File "/data/isip/exp/tuh_dpath/exp_0280/nedc_mladp/lib/nedc_mladp_eval_tools.py", line 7, in <module>
    import polars
ModuleNotFoundError: No module named 'polars'
Traceback (most recent call last):
  File "/data/isip/exp/tuh_dpath/exp_0280/nedc_mladp/bin/./nedc_mladp_eval", line 21, in <module>
    import nedc_mladp_eval_tools as eval_tools
  File "/data/isip/exp/tuh_dpath/exp_0280/nedc_mladp/lib/nedc_mladp_eval_tools.py", line 7, in <module>
    import polars
ModuleNotFoundError: No module named 'polars'
before =  1519 1519
after =  1519 1519
Traceback (most recent call last):
  File "/data/isip/exp/tuh_dpath/exp_0280/nedc_mladp/bin/./nedc_mladp_eval", line 92, in <module>
    main()
  File "/data/isip/exp/tuh_dpath/exp_0280/nedc_mladp/bin/./nedc_mladp_eval", line 80, in main
    eval_tools.plot_decisions(model,mydata,decisions_path,frame_locations,framesizes)
  File "/data/isip/exp/tuh_dpath/exp_0280/nedc_mladp/lib/nedc_mladp_eval_tools.py", line 140, in plot_decisions
    df.write_csv(output_path)
  File "/data/isip/exp/tuh_dpath/exp_0280/venv/lib/python3.9/site-packages/polars/_utils/deprecation.py", line 134, in wrapper
    return function(*args, **kwargs)
  File "/data/isip/exp/tuh_dpath/exp_0280/venv/lib/python3.9/site-packages/polars/_utils/deprecation.py", line 134, in wrapper
    return function(*args, **kwargs)
  File "/data/isip/exp/tuh_dpath/exp_0280/venv/lib/python3.9/site-packages/polars/dataframe/frame.py", line 2577, in write_csv
    self._df.write_csv(
FileNotFoundError: No such file or directory (os error 2)
Traceback (most recent call last):
  File "/data/isip/exp/tuh_dpath/exp_0280/nedc_mladp/bin/./nedc_mladp_eval", line 92, in <module>
    main()
  File "/data/isip/exp/tuh_dpath/exp_0280/nedc_mladp/bin/./nedc_mladp_eval", line 60, in main
    feature_files_list = fileio_tools.read_file_lists(feature_data_list)
  File "/data/isip/exp/tuh_dpath/exp_0280/nedc_mladp/lib/nedc_mladp_fileio_tools.py", line 15, in read_file_lists
    file1 = open(file_name, 'r')
FileNotFoundError: [Errno 2] No such file or directory: '/data/isip/exp/tuh_dpath/exp_0280/nedc_mladp/data/TRAIN/dcts1.list'
before =  1519 1519
after =  1519 1519
Accuracy rate =  0.9506254114549045
Mean confidence % 0.8137788018433232
Traceback (most recent call last):
  File "/data/isip/exp/tuh_dpath/exp_0280/nedc_mladp/bin/./nedc_mladp_gen_graphics", line 150, in <module>
    main()
  File "/data/isip/exp/tuh_dpath/exp_0280/nedc_mladp/bin/./nedc_mladp_gen_graphics", line 92, in main
    header, ids, labels, coordinates = fileio_tools.parse_annotations(label_file)
  File "/data/isip/exp/tuh_dpath/exp_0280/nedc_mladp/lib/nedc_mladp_fileio_tools.py", line 106, in parse_annotations
    header,data = nadt.read(file)
  File "/data/isip/tools/linux_x64/nfc/lib/nedc_ann_dpath_tools.py", line 191, in read
    elif ann.is_csv(fname):
  File "/data/isip/tools/linux_x64/nfc/lib/nedc_ann_dpath_tools.py", line 475, in is_csv
    header = fp.readline()
  File "/data/isip/tools/linux_x64/common/anaconda3/conda/envs/nedc/lib/python3.9/codecs.py", line 322, in decode
    (result, consumed) = self._buffer_decode(data, self.errors, final)
UnicodeDecodeError: 'utf-8' codec can't decode byte 0xed in position 6: invalid continuation byte
